<?xml version="1.0"?>
<robot xmlns:xacro="http://www.ros.org/wiki/xacro" name="bcr_bot">

<!-- .......................................................Base Link.........................................................................................................-->
     <!-- Base Link -->
  <link name="base_link"/>

  <!-- Chassis Link -->
  <link name="chassis_link">
    <inertial>
      <origin xyz="-0.151427 0 0.175" rpy="0 0 0"/>
      <mass value="1.14395"/>
      <inertia ixx="0.126164" ixy="0" ixz="0" iyy="0.416519" iyz="0" izz="0.481014"/>
    </inertial>
    <visual name="visual">
      <origin xyz="-0.151427 0 0.175" rpy="0 0 0"/>
      <geometry>
        <box size="2.01142 1 0.568726"/>
      </geometry>
      <material name="blue_material">
        <color rgba="0.5 0.5 1.0 1"/>
      </material>
    </visual>
    <collision name="collision">
      <origin xyz="-0.151427 0 0.175" rpy="0 0 0"/>
      <geometry>
        <box size="2.01142 1 0.568726"/>
      </geometry>
    </collision>
  </link>

  <joint name="chassis_joint" type="fixed">
    <parent link="base_link"/>
    <child link="chassis_link"/>
    <origin xyz="0.0 0 0" rpy="0 0 0"/>
  </joint>

  <!-- LIDAR -->
  <link name="two_d_lidar">
    <collision>
      <origin xyz="0 0 0.4" rpy="0 0 0"/>
      <geometry>
        <box size="0.1 0.1 0.1"/>
      </geometry>
    </collision>
    <visual>
      <origin xyz="0 0 0.4" rpy="0 0 0"/>
      <geometry>
        <box size="0.1 0.1 0.1"/>
      </geometry>
      <material name="">
        <color rgba="1 0 0 1"/>
      </material>
    </visual>
    <inertial>
      <origin xyz="0 0 0.4" rpy="0 0 0"/>
      <mass value="0.1"/>
      <inertia ixx="0.001" ixy="0.0" ixz="0.0" iyy=".001" iyz="0.0" izz="0.001"/>
    </inertial>
  </link>

  <joint name="two_d_lidar_joint" type="fixed">
    <parent link="base_link"/>
    <child link="two_d_lidar"/>
    <origin xyz="0.0 0 0.4" rpy="0 0 0"/>
  </joint>

  <!-- Front Left Steering -->
  <link name="front_left_wheel_steering_link">
    <inertial>
      <origin xyz="0 0 0" rpy="0 0 0"/>
      <mass value="0.5"/>
      <inertia ixx="0.0153" ixy="0" ixz="0" iyy="0.025" iyz="0" izz="0.0153"/>
    </inertial>
    <visual>
      <origin xyz="0 0 0" rpy="0 0 0"/>
      <geometry>
        <cylinder length="0.1" radius="0.03"/>
      </geometry>
      <material name="">
        <color rgba="1 1 1 1"/>
      </material>
    </visual>
  </link>

  <joint name="front_left_wheel_steering_joint" type="revolute">
    <parent link="base_link"/>
    <child link="front_left_wheel_steering_link"/>
    <origin xyz="0.554283 0.5 0.02" rpy="0 0 0"/>
    <axis xyz="0 0 1"/>
    <limit lower="-0.6" upper="0.6" effort="25" velocity="1.0"/>
  </joint>

  <!-- Front Right Steering -->
  <link name="front_right_wheel_steering_link">
    <inertial>
      <origin xyz="0 0 0" rpy="0 0 0"/>
      <mass value="0.5"/>
      <inertia ixx="0.0153" ixy="0" ixz="0" iyy="0.025" iyz="0" izz="0.0153"/>
    </inertial>
    <visual>
      <origin xyz="0 0 0" rpy="0 0 0"/>
      <geometry>
        <cylinder length="0.1" radius="0.03"/>
      </geometry>
      <material name="">
        <color rgba="1 1 1 1"/>
      </material>
    </visual>
  </link>

  <joint name="front_right_wheel_steering_joint" type="revolute">
    <parent link="base_link"/>
    <child link="front_right_wheel_steering_link"/>
    <origin xyz="0.554283 -0.5 0.02" rpy="0 0 0"/>
    <axis xyz="0 0 1"/>
    <limit lower="-0.6" upper="0.6" effort="25" velocity="1.0"/>
  </joint>

  <!-- Front Left Wheel -->
  <link name="front_left_wheel">
    <inertial>
      <origin xyz="0 0 0" rpy="-1.5707 0 0"/>
      <mass value="2"/>
      <inertia ixx="0.145833" ixy="0" ixz="0" iyy="0.145833" iyz="0" izz="0.125"/>
    </inertial>
    <visual name="visual">
      <origin xyz="0 0 0" rpy="-1.5707 0 0"/>
      <geometry>
        <cylinder length="0.15" radius="0.3"/>
      </geometry>
      <material name="">
        <color rgba="0.2 0.2 0.2 1"/>
      </material>
    </visual>
    <collision name="collision">
      <origin xyz="0 0 0" rpy="-1.5707 0 0"/>
      <geometry>
        <cylinder length="0.15" radius="0.3"/>
      </geometry>
    </collision>
  </link>

  <joint name="front_left_wheel_joint" type="continuous">
    <parent link="front_left_wheel_steering_link"/>
    <child link="front_left_wheel"/>
    <origin xyz="0 0.2 0" rpy="0 0 0"/>
    <axis xyz="0 1 0"/>
  </joint>

  <!-- Front Right Wheel -->
  <link name="front_right_wheel">
    <inertial>
      <origin xyz="0 0 0" rpy="-1.5707 0 0"/>
      <mass value="2"/>
      <inertia ixx="0.145833" ixy="0" ixz="0" iyy="0.145833" iyz="0" izz="0.125"/>
    </inertial>
    <visual>
      <origin xyz="0 0 0" rpy="-1.5707 0 0"/>
      <geometry>
        <cylinder length="0.15" radius="0.3"/>
      </geometry>
      <material name="">
        <color rgba="0.2 0.2 0.2 1"/>
      </material>
    </visual>
    <collision>
      <origin xyz="0 0 0" rpy="-1.5707 0 0"/>
      <geometry>
        <cylinder length="0.15" radius="0.3"/>
      </geometry>
    </collision>
  </link>

  <joint name="front_right_wheel_joint" type="continuous">
    <parent link="front_right_wheel_steering_link"/>
    <child link="front_right_wheel"/>
    <origin xyz="0 -0.2 0" rpy="0 0 0"/>
    <axis xyz="0 1 0"/>
  </joint>

  <!-- Rear Left Wheel -->
  <link name="rear_left_wheel">
    <inertial>
      <origin xyz="0 0 0" rpy="-1.5707 0 0"/>
      <mass value="2"/>
      <inertia ixx="0.145833" ixy="0" ixz="0" iyy="0.145833" iyz="0" izz="0.125"/>
    </inertial>
    <visual name="visual">
      <origin xyz="0 0 0" rpy="-1.5707 0 0"/>
      <geometry>
        <cylinder length="0.15" radius="0.3"/>
      </geometry>
      <material name="">
        <color rgba="0.2 0.2 0.2 1"/>
      </material>
    </visual>
    <collision name="collision">
      <origin xyz="0 0 0" rpy="-1.5707 0 0"/>
      <geometry>
        <cylinder length="0.15" radius="0.3"/>
      </geometry>
    </collision>
  </link>

  <joint name="rear_left_wheel_joint" type="continuous">
    <parent link="base_link"/>
    <child link="rear_left_wheel"/>
    <origin xyz="-0.957138 0.625029 -0.025" rpy="0 0 0"/>
    <axis xyz="0 1 0"/>
  </joint>

  <!-- Rear Right Wheel -->
  <link name="rear_right_wheel">
    <inertial>
      <origin xyz="0 0 0" rpy="-1.5707 0 0"/>
      <mass value="2"/>
      <inertia ixx="0.145833" ixy="0" ixz="0" iyy="0.145833" iyz="0" izz="0.125"/>
    </inertial>
    <visual name="visual">
      <origin xyz="0 0 0" rpy="-1.5707 0 0"/>
      <geometry>
        <cylinder length="0.15" radius="0.3"/>
      </geometry>
      <material name="">
        <color rgba="0.2 0.2 0.2 1"/>
      </material>
    </visual>
    <collision name="collision">
      <origin xyz="0 0 0" rpy="-1.5707 0 0"/>
      <geometry>
        <cylinder length="0.15" radius="0.3"/>
      </geometry>
    </collision>
  </link>

  <joint name="rear_right_wheel_joint" type="continuous">
    <parent link="base_link"/>
    <child link="rear_right_wheel"/>
    <origin xyz="-0.957138 -0.625029 -0.025" rpy="0 0 0"/>
    <axis xyz="0 1 0"/>
  </joint>

  <!-- ..................................................GAZEBO SENSORS AND PLUGINS ............................................. -->
 <gazebo>
        <plugin filename="ignition-gazebo-sensors-system" name="ignition::gazebo::systems::Sensors">
            <render_engine>ogre2</render_engine>
        </plugin>

        <plugin filename="ignition-gazebo-imu-system" name="ignition::gazebo::systems::Imu">
        </plugin>

        <plugin filename="ignition-gazebo-joint-state-publisher-system" name="ignition::gazebo::systems::JointStatePublisher">
        </plugin>
        <plugin
        filename="ignition-gazebo-scene-broadcaster-system"
        name="gz::sim::systems::SceneBroadcaster">
        </plugin>
        <plugin
        filename="ignition-gazebo-user-commands-system"
        name="gz::sim::systems::UserCommands">
        </plugin>

        <!-- ...........................ACKERMANN STEERING PLUGIN ................................... -->

        <plugin
            filename="ignition-gazebo-ackermann-steering-system"
            name="gz::sim::systems::AckermannSteering">
            <left_joint>front_left_wheel_joint</left_joint>
            <left_joint>rear_left_wheel_joint</left_joint>
            <right_joint>front_right_wheel_joint</right_joint>
            <right_joint>rear_right_wheel_joint</right_joint>
            <left_steering_joint>front_left_wheel_steering_joint</left_steering_joint>
            <right_steering_joint>front_right_wheel_steering_joint</right_steering_joint>
            <kingpin_width>1.0</kingpin_width>
            <steering_limit>0.5</steering_limit>
            <wheel_base>1.0</wheel_base>
            <wheel_separation>1.25</wheel_separation>
            <wheel_radius>0.3</wheel_radius>
            <min_velocity>-3</min_velocity>
            <max_velocity>14</max_velocity>
            <min_acceleration>-3</min_acceleration>
            <max_acceleration>3</max_acceleration>
            <topic>/cmd_vel</topic>
            <!-- <odom_topic>$(arg wheel_odom_topic)</odom_topic>
            <tf_topic>/tf</tf_topic>
            <frame_id>odom</frame_id> -->
            <!-- <child_frame_id>base_link</child_frame_id>  -->

        </plugin>
    </gazebo>

    <!-- ............................. ground truth .................................... -->

    <gazebo>
        <plugin filename="libignition-gazebo6-odometry-publisher-system"
            name="ignition::gazebo::systems::OdometryPublisher">
            <odom_frame>odom</odom_frame>
            <robot_base_frame>base_link</robot_base_frame>
            <odom_topic>odom</odom_topic>
            <tf_topic>/tf</tf_topic>
            <dimensions>2</dimensions>
            <odom_publish_frequency>10</odom_publish_frequency>
        </plugin>
    </gazebo>
    

    <!-- ........................... 2D LIDAR config ................................... -->

    <gazebo reference="two_d_lidar">
        <sensor name='gpu_lidar' type='gpu_lidar'>
            <topic>scan</topic>
            <update_rate>10</update_rate>
            <ignition_frame_id>two_d_lidar</ignition_frame_id>
            <lidar>
                <scan>
                    <horizontal>
                        <samples>48</samples>
                        <resolution>1</resolution>
                        <min_angle>${radians(-120)}</min_angle>
                        <max_angle>${radians(120)}</max_angle>
                    </horizontal>
                    <vertical>
                      <samples>1</samples>
                      <resolution>1</resolution>
                      <min_angle>0.0</min_angle>
                      <max_angle>0.0</max_angle>
                    </vertical>
                </scan>
                <range>
                    <min>1</min>
                    <max>100</max>
                    <resolution>0.1</resolution>
                </range>
                <!-- <noise>
                    <type>gaussian</type>
                    <mean>0.0</mean>
                    <stddev>0.001</stddev>
                </noise> -->
            </lidar>
            <alwaysOn>1</alwaysOn>
            <visualize>true</visualize>
        </sensor>
    </gazebo>
  
  </robot>
